<?xml version="1.0" ?>
<robot name="indy7" xmlns:xacro="http://www.ros.org/wiki/xacro">
  <material name="black">
    <color rgba="0.0 0.0 0.0 1.0"/>
  </material>
  <material name="blue">
    <color rgba="0.0 0.0 0.8 1.0"/>
  </material>
  <material name="green">
    <color rgba="0.0 0.8 0.0 1.0"/>
  </material>
  <material name="grey_">
    <color rgba="0.2 0.2 0.2 1.0"/>
  </material>
  <material name="orange">
    <color rgba="1.0 0.423529411765 0.0392156862745 1.0"/>
  </material>
  <material name="brown">
    <color rgba="0.870588235294 0.811764705882 0.764705882353 1.0"/>
  </material>
  <material name="red">
    <color rgba="0.8 0.0 0.0 1.0"/>
  </material>
  <material name="white">
    <color rgba="1.0 1.0 1.0 1.0"/>
  </material>
  <material name="metal">
    <color rgba="0.768627450980392 0.749019607843137 0.729411764705882 1"/>
  </material>
  <material name="metal_grey">
    <color rgba="0.501960784313725 0.501960784313725 0.501960784313725 1"/>
  </material>
  <material name="metal_white">
    <color rgba="0.866666666666667 0.866666666666667 0.890196078431373 1"/>
  </material>

<link name="world">
  </link>
  <joint name="world_fixed" type="fixed">
    <origin rpy="0 0 0" xyz="0 0 0"/>
    <parent link="world"/>
    <child link="base_link"/>
  </joint>
<link name="base_link"/>
   <joint name="base_joint" type="fixed">
    <parent link="base_link"/>
    <child link="link0"/>
    <origin rpy="0 0 0" xyz="0 0 0"/>
    <axis xyz="0 0 1"/>
    <limit effort="10" lower="-3.05432619099" upper="3.05432619099" velocity="1"/>
  </joint>
<link name="link0">
 <inertial>
      <origin rpy="0 0 0" xyz="0 0 0"/>
      <mass value="1.59306955" />
      <inertia ixx="+0.00572623" iyy="+0.00558959" izz="+0.00966674" ixy="+0.00000251" iyz="-0.00000014" ixz="-0.00011380"/>
    </inertial>
    <visual>
      <origin rpy="0 0 0" xyz="0 0 0"/>
      <geometry>
        <mesh filename="meshes/Indy7_0.stl"/>
      </geometry>
      <material name="metal_grey"/>
    </visual>
    <collision>
      <origin rpy="0 0 0" xyz="0 0 0"/>
      <geometry>
        <mesh filename="meshes/Indy7_0.stl"/>
      </geometry>
    </collision>
  </link>
<link name="link1">
   <inertial>
      <origin rpy="0 0 0" xyz="0 0 0"/>
      <mass value="11.8030102"/>
      <inertia ixx="+0.15418559" iyy="+0.12937017" izz="+0.05964415" ixy="-0.00000235" iyz="-0.04854267" ixz="+0.00001739"/>
    </inertial>
    <visual>
      <origin rpy="0 0 0" xyz="0 0 0"/>
      <geometry>
        <mesh filename="meshes/Indy7_1.stl"/>
      </geometry>
      <material name="metal_white"/>
    </visual>
    <collision>
      <origin rpy="0 0 0" xyz="0 0 0"/>
      <geometry>
        <mesh filename="meshes/Indy7_1.stl"/>
      </geometry>
    </collision>
</link>
 <link name="link2">
 <inertial>
      <origin rpy="0 0 0" xyz="0 0 0"/>
      <mass value="7.99292141"/>
      <inertia ixx="+0.29356980" iyy="+0.28094142" izz="+0.03620609" ixy="-0.00000040" iyz="+0.03727972" ixz="+0.00001441"/>
    </inertial>
    <visual>
      <origin rpy="0 0 0" xyz="0 0 0"/>
      <geometry>
        <mesh filename="meshes/Indy7_2.stl"/>
      </geometry>
      <material name="metal_white"/>
    </visual>
    <collision>
      <origin rpy="0 0 0" xyz="0 0 0"/>
      <geometry>
        <mesh filename="meshes/Indy7_2.stl"/>
      </geometry>
    </collision>
  </link>

 <link name="link3">
   <inertial>
      <origin rpy="0 0 0" xyz="0 0 0"/>
      <mass value="2.99134127"/>
      <inertia ixx="+0.03424593" iyy="+0.03406024" izz="+0.00450477" ixy="+0.00000149" iyz="+0.00186009" ixz="+0.00000724"/>
    </inertial>
    <visual>
      <origin rpy="0 0 0" xyz="0 0 0"/>
      <geometry>
        <mesh filename="meshes/Indy7_3.stl"/>
      </geometry>
      <material name="metal_white"/>
    </visual>
    <collision>
      <origin rpy="0 0 0" xyz="0 0 0"/>
      <geometry>
        <mesh filename="meshes/Indy7_3.stl"/>
      </geometry>
    </collision>
  </link>
  <link name="link4">
    <inertial>
      <origin rpy="0 0 0" xyz="0 0 0"/>
      <mass value="2.12317035"/>
      <inertia ixx="+0.00670405" iyy="+0.00279246" izz="+0.00619341" ixy="+0.00000375" iyz="-0.00127967" ixz="+0.00000150"/>
    </inertial>
    <visual>
      <origin rpy="0 0 0" xyz="0 0 0"/>
      <geometry>
        <mesh filename="meshes/Indy7_4.stl"/>
      </geometry>
      <material name="metal_white"/>
    </visual>
    <collision>
      <origin rpy="0 0 0" xyz="0 0 0"/>
      <geometry>
        <mesh filename="meshes/Indy7_4.stl"/>
      </geometry>
    </collision>
  </link>
  <link name="link5">
    <inertial>
      <origin rpy="0 0 0" xyz="0 0 0"/>
     <mass value="2.28865091"/>
      <inertia ixx="+0.00994891" iyy="+0.00978189" izz="+0.00271492" ixy="+0.00000014" iyz="-0.00093546" ixz="+0.00000321"/>
    </inertial>
    <visual>
      <origin rpy="0 0 0" xyz="0 0 0"/>
      <geometry>
        <mesh filename="meshes/Indy7_5.stl"/>
      </geometry>
      <material name="metal_white"/>
    </visual>
    <collision>
      <origin rpy="0 0 0" xyz="0 0 0"/>
      <geometry>
        <mesh filename="meshes/Indy7_5.stl"/>
      </geometry>
    </collision>

  </link>
  <link name="link6">
    <inertial>
      <origin rpy="0 0 0" xyz="0 0 0"/>
      <mass value="0.40083918"/>
      <inertia ixx="0.00043534" iyy="0.00044549" izz="0.00059634" ixy="+0.00000013" iyz="+0.00000051" ixz="-0.00000002"/>
    </inertial>
    <visual>
      <origin rpy="0 0 0" xyz="0 0 0"/>
      <geometry>
        <mesh filename="meshes/Indy7_6.stl"/>
      </geometry>
      <material name="metal_white"/>
    </visual>
    <collision>
      <origin rpy="0 0 0" xyz="0 0 0"/>
      <geometry>
        <mesh filename="meshes/Indy7_6.stl"/>
      </geometry>
    </collision>
  </link>
  <link name="gripper_link">
    <inertial>
      <origin rpy="0 0 0" xyz="0 0 0"/>
      <mass value="0.5"/>
      <inertia ixx="0.00043534" iyy="0.00044549" izz="0.00059634" ixy="+0.00000013" iyz="+0.00000051" ixz="-0.00000002"/>
    </inertial>
    <visual>
      <origin rpy="0 0 0" xyz="0 0 0"/>
      <geometry>
        <mesh filename="meshes/stl/gripper.stl"/>
      </geometry>
      <material name="black"/>
    </visual>
    <collision>
      <origin rpy="0 0 0" xyz="0 0 0"/>
      <geometry>
        <mesh filename="meshes/stl/gripper.stl"/>
      </geometry>
    </collision>
  </link>
  <link name="tcp"/>

  <joint name="joint0" type="continuous">
    <parent link="link0"/>
    <child link="link1"/>
    <origin xyz="0 0 0.0775" rpy="0 0 0"/>
    <axis xyz = "0 0 1"/>
       <!--<limit effort="300" lower="-3.054325556" upper="3.054325556" velocity="10"/>
    <dynamics damping="0.5"/>-->
  </joint>


 <joint name="joint1" type="continuous">
    <parent link="link1"/>
    <child link="link2"/>
    <origin xyz = "0 -0.10900000 0.22200000" rpy = "1.570796 1.570796 0"/>
      <axis xyz = "0 0 1"/>
   <!-- <limit effort="300" lower="-3.054325556" upper="3.054325556" velocity="10"/>
    <dynamics damping="0.5"/>-->
  </joint>

  <joint name="joint2" type="continuous">
    <parent link="link2"/>
    <child link="link3"/>
    <origin xyz = "-0.45000000 +0.00000000 -0.03050000" rpy = "0 0 0"/>
      <axis xyz = "0 0 1"/>
       <!--<limit effort="300" lower="-3.054325556" upper="3.054325556" velocity="10"/>
    <dynamics damping="0.5"/>-->
  </joint>
  <joint name="joint3" type="continuous">
    <parent link="link3"/>
    <child link="link4"/>
      <origin xyz = "-0.26700000 +0.00000000 -0.07500000" rpy = "-1.570796 0 1.570796"/>
      <axis xyz = "0 0 1"/>
      <!-- <limit effort="300" lower="-3.054325556" upper="3.054325556" velocity="10"/>
    <dynamics damping="0.5"/>-->
  </joint>

  <joint name="joint4" type="continuous">
    <parent link="link4"/>
    <child link="link5"/>
    <origin xyz = "+0.00000000 -0.11400000 +0.08300000" rpy = "1.570796 1.570796 0"/>
    <axis xyz = "0 0 1"/>
      <!-- <limit effort="300" lower="-3.054325556" upper="3.054325556" velocity="10"/>
    <dynamics damping="0.5"/>-->
  </joint>

  <joint name="joint5" type="continuous">
    <parent link="link5"/>
    <child link="link6"/>
    <origin xyz = "-0.16800000 +0.00000000 +0.06900000" rpy = "-1.570796 0 1.570796"/>
      <axis xyz = "0 0 1"/>
       <!--<limit effort="300" lower="-3.054325556" upper="3.054325556" velocity="10"/>
    <dynamics damping="0.5"/>-->
  </joint>

  <joint name="gripper" type="fixed">
    <parent link="link6"/>
    <child link="gripper_link"/>
    <origin xyz="0 0 0.06" rpy="0 0 0"/>
  </joint>
  <joint name="tcp" type="fixed">
    <parent link="gripper_link"/>
    <child link="tcp"/>
    <origin xyz="0 0 0.06" rpy="0 0 0"/>
  </joint>


</robot>
